Workbook

Sheet Executive Summary
A1: HEALTH TRIXSS | MAO-004 Provider Corrective-Action Workbook
A2: Decision support that separates the CMS-coded MAO-004 outcome from the evidence required to establish the operational root cause.
A4: Core Operating Principle
A5: CMS Fields #25 and #27 describe the final filtering outcome, but they do not uniquely identify the operational root cause. Start with MAO-004 Field #23 Service Type to determine the applicable filtering path. For H outcomes, reconcile CPT/HCPCS from the provider claim, plan encounter, and MAO-002 line detail; for T outcomes, reconcile Type of Bill from the 837I and plan encounter; for D outcomes, use MAO-004 Fields #17, #19, and #21 plus provider/plan submission timestamps; and for linked or blank transactions, use Fields #11, #13, #15, #31, #33, and #35. CPT/HCPCS and Type of Bill are source/encounter data—not separate MAO-004 detail fields.
A8: Root-Cause Scenarios | C8: Provider / Shared | E8: Plan / CMS Controlled | G8: Required Data Points
A9: =COUNTA('Provider Action Matrix'!A5:A18) -> 14 | C9: =COUNTIF('Provider Action Matrix'!I5:I18,"Provider / Shared")+COUNTIF('Provider Action Matrix'!I5:I18,"Provider for prevention")+COUNTIF('Provider Action Matrix'!I5:I18,"Provider or Plan")+COUNTIF('Provider Action Matrix'!I5:I18,"Shared / Plan-led")+COUNTIF('Provider Action Matrix'!I5:I18,"Depends on MAO-002 edit") -> 6 | E9: =COUNTIF('Provider Action Matrix'!I5:I18,"Plan / Vendor")+COUNTIF('Provider Action Matrix'!I5:I18,"CMS rule / No provider defect")+COUNTIF('Provider Action Matrix'!I5:I18,"CMS / Plan reconciliation")+COUNTIF('Provider Action Matrix'!I5:I18,"No provider defect") -> 8 | G9: =COUNTA('Plan Data Requirements'!A26:A42) -> 17
A12: Provider Decision Workflow
A13: Step | B13: Question | E13: Decision / Action | H13: Primary Owner
A14: 1 | B14: What MAO-004 status and reason did CMS return? | E14: Treat the combination as the coded outcome family—not as the final root-cause determination. | H14: Plan risk-adjustment operations
A15: 2 | B15: What occurred at the encounter and service-line level? | E15: Pull MAO-002 header/line status, affected line number, edit code, and edit description. | H15: Plan encounter-data team
A16: 3 | B16: Do provider source values match the plan-submitted EDPS values? | E16: Compare CPT/HCPCS, Type of Bill, claim type, diagnosis linkage, service lines, and transaction history. | H16: Provider EDI and plan encounter operations
A17: 4 | B17: Which evidence proves the timing and ownership? | E17: Compare provider submission, clearinghouse acceptance, plan receipt, adjudication, EDPS submission, and CMS deadline. | H17: Provider relations / delegated oversight
A18: 5 | B18: Where must the correction occur? | E18: Fix supported source-claim errors at the provider; fix mapping, linkage, construction, and EDPS errors at the plan/vendor. | H18: Confirmed root-cause owner
A21: Provider Control Legend
A22: Provider / Shared | C22: Provider evidence demonstrates a supported source-data correction, but the plan must process and submit the corrected EDPS transaction.
A23: Plan / CMS Controlled | C23: The provider source claim is accurate, or the failure occurred in plan mapping, linkage, encounter construction, timing, or CMS filtering.
A24: Outcome ≠ Root Cause | C24: The same MAO-004 result can represent multiple scenarios. Use the Scenario ID and required-data decision test before assigning accountability.
A27: Health Trixss operational reference | Educational and workflow support only; apply current CMS guidance, contract terms, and compliance review.

Sheet Provider Action Matrix
A1: HEALTH TRIXSS | MAO-004 Provider Root-Cause & Corrective-Action Matrix
A2: CMS supplies Fields #25 and #27 as the coded outcome. Use MAO-004 service, submission, and linkage fields plus source-claim and MAO-002 detail to establish the actual root cause.
A3: ROOT-CAUSE FIELD LOGIC: Start with Field #23 Service Type. For Reason H, evaluate CPT/HCPCS from the source claim/837 and MAO-002 line results. For Reason T, evaluate Type of Bill from the 837I/plan encounter. For Reason D, use Fields #17, #19, and #21 with submission timestamps and the CMS deadline. For linked/blank transactions, use Fields #11, #13, #15, #31, #33, and #35. CPT/HCPCS and Type of Bill are not discrete MAO-004 detail fields.
A4: Scenario ID | B4: MAO-004 Result Combination | C4: MAO-004 Status (#25) | D4: MAO-004 Reason (#27) | E4: Root-Cause Field(s) Used with #25/#27 | F4: CMS-Coded Outcome | G4: Additional Data Required to Confirm Root Cause | H4: Root-Cause Decision Test | I4: Confirmed Control Owner | J4: Corrective Action | K4: Where the Fix Occurs
A5: A-01 | B5: A + blank | C5: A | D5: Blank | E5: MAO-004 #23 Service Type determines the filtering path. For P/O/DME, compare source and plan-submitted CPT/HCPCS; for I/O, compare Type of Bill. CPT/HCPCS and Type of Bill are not discrete MAO-004 detail fields. | F5: CMS allowed the diagnosis after applying the applicable risk-adjustment filtering. | G5: MAO-002 acceptance; source claim; plan encounter record; MAO-004 row; MOR/HCC reconciliation. | H5: Confirm the provider source values and plan-submitted encounter values match. If they match, an absent HCC is not an MAO-004 rejection root cause. | I5: No provider defect | J5: No MAO-004 correction. Reconcile downstream HCC/model results. Correct the source claim only when a factual coding or diagnosis error is identified. | K5: Plan risk-adjustment reconciliation; provider EHR/coding only for a supported source-data correction.
A6: H-01 | B6: D + H | C6: D | D6: H | E6: MAO-004 #23 Service Type + provider/plan CPT/HCPCS values + MAO-002 accepted-line status. Use CPT/HCPCS because #27=H; the actual procedure code must come from the 837/claim or plan encounter extract. | F6: CMS found no accepted service line containing an allowable CPT/HCPCS code. | G6: Medical record; charge detail; provider source claim; submitted CPT/HCPCS; accepted service lines. | H6: The medical record supports a different procedure, an omitted qualifying service, or a source-claim configuration error. | I6: Provider / Shared | J6: Submit a supported corrected claim. The plan must process it and submit the corrected or replacement encounter to EDPS. | K6: Provider coding, charge capture, claim scrubber, or billing system; then the plan encounter-submission process.
A7: H-02 | B7: D + H | C7: D | D7: H | E7: MAO-004 #23 Service Type + MAO-002 line number, line status, five-digit edit code, and provider/plan CPT/HCPCS. This distinguishes a rejected qualifying line from an absent or nonqualifying line. | F7: CMS found no accepted service line containing an allowable CPT/HCPCS code. | G7: MAO-002 line number; accepted/rejected status; five-digit edit code and description; provider source line. | H7: The qualifying procedure exists on the provider claim, but the qualifying line is rejected on MAO-002. | I7: Depends on MAO-002 edit | J7: Correct the exact rejected data element when it originated in provider data; otherwise require the plan/vendor to correct the encounter construction or submission. | K7: Provider billing/EDI, clearinghouse, or plan encounter platform—determined by the specific edit and source-to-EDPS comparison.
A8: H-03 | B8: D + H | C8: D | D8: H | E8: MAO-004 #23 Service Type + all accepted CPT/HCPCS lines + the applicable service-year allowable CPT/HCPCS list. CPT/HCPCS values are obtained outside MAO-004. | F8: CMS found no accepted service line containing an allowable CPT/HCPCS code. | G8: All accepted lines; provider source claim; applicable service-year allowable CPT/HCPCS logic. | H8: The source claim and EDPS encounter match, and every accepted procedure accurately represents a legitimately nonqualifying service. | I8: CMS rule / No provider defect | J8: Do not alter the claim. Determine whether another valid, documented, eligible encounter supports the diagnosis. | K8: No correction to the existing claim; plan risk-adjustment reconciliation and other-encounter review.
A9: H-04 | B9: D + H | C9: D | D9: H | E9: MAO-004 #23 Service Type + provider 837/claim CPT/HCPCS + plan-submitted EDPS line values + MAO-002 line detail. A source-to-EDPS mismatch identifies a plan/vendor construction issue. | F9: CMS found no accepted service line containing an allowable CPT/HCPCS code. | G9: Provider 837/claim image; plan-adjudicated claim; plan EDPS encounter extract; MAO-002 line detail. | H9: The provider source claim contains the qualifying line, but the plan-submitted EDPS record omitted, altered, or failed to propagate it. | I9: Plan / Vendor | J9: Correct the plan mapping, encounter construction, replacement linkage, or submission logic and resubmit the accurate encounter. | K9: MA-plan encounter warehouse, EDI mapping layer, delegated submitter, or encounter-data vendor.
A10: T-01 | B10: D + T | C10: D | D10: T | E10: MAO-004 #23 Service Type + provider and plan-submitted Type of Bill + MAO-002 preliminary reason PT when available. Type of Bill is obtained from the 837I/claim or plan encounter extract, not from a separate MAO-004 field. | F10: CMS determined the institutional Type of Bill was not allowable under the filtering logic. | G10: Medical record; care setting; provider UB-04/837I; source Type of Bill; plan-submitted Type of Bill. | H10: The actual setting or transaction supports a different Type of Bill than the value on the provider source claim. | I10: Provider / Shared | J10: Submit a supported corrected institutional claim. The plan must submit the corrected or replacement encounter. | K10: Facility patient-accounting or institutional-billing system; then plan institutional EDI/EDPS processing.
A11: T-02 | B11: D + T | C11: D | D11: T | E11: MAO-004 #23 Service Type + accurate source/plan Type of Bill + applicable CMS Type-of-Bill eligibility logic. Matching values with a nonqualifying setting indicate no provider defect. | F11: CMS determined the institutional Type of Bill was not allowable under the filtering logic. | G11: Provider source Type of Bill; plan EDPS Type of Bill; care-setting evidence; applicable CMS filtering logic. | H11: The source and EDPS values match, the Type of Bill is accurate, and the setting is legitimately nonqualifying. | I11: CMS rule / No provider defect | J11: Do not change an accurate Type of Bill. Search for another eligible, documented encounter when appropriate. | K11: No source-claim correction; plan risk-adjustment reconciliation.
A12: T-03 | B12: D + T | C12: D | D12: T | E12: MAO-004 #23 Service Type + source/plan Type of Bill + #13 Linked ICN + #15 linked-record status + active encounter history. Use these fields to detect stale or incorrectly linked institutional records. | F12: CMS determined the institutional Type of Bill was not allowable under the filtering logic. | G12: Provider 837I; corrected-claim history; plan encounter extract; active and linked ICNs; MAO-002/MAO-004 history. | H12: The provider submitted the accurate or corrected Type of Bill, but the plan EDPS record differs or an older encounter remains active. | I12: Plan / Vendor | J12: Correct the plan mapping or active-record linkage and submit the accurate replacement, void, or correction. | K12: Plan institutional EDI, encounter repository, ICN-linkage process, or delegated encounter vendor.
A13: D-01 | B13: D + D | C13: D | D13: D | E13: MAO-004 #17 Encounter Submission Date + #19 From DOS + #21 Through DOS + applicable CMS deadline. Supplement with provider transmission, clearinghouse acceptance, and plan receipt timestamps. | F13: CMS applied the applicable risk-adjustment submission deadline condition. | G13: Date of service; provider claim creation and submission; clearinghouse acceptance; plan receipt; correction date; CMS deadline. | H13: The provider's original or corrected transaction reached the plan too late to complete the CMS submission process. | I13: Provider for prevention | J13: Submit the accurate transaction, then remediate unbilled accounts, coding holds, claim edits, clearinghouse rejects, and correction turnaround. | K13: Provider revenue-cycle, coding, medical-record completion, and EDI work queues.
A14: D-02 | B14: D + D | C14: D | D14: D | E14: MAO-004 #17 Encounter Submission Date + #19/#21 DOS + CMS deadline, compared with provider receipt, plan adjudication, queue, and EDPS submission timestamps. | F14: CMS applied the applicable risk-adjustment submission deadline condition. | G14: Provider submission and payer-receipt proof; plan adjudication date; exception-queue history; EDPS submission timestamp; CMS deadline. | H14: The plan received complete data timely but submitted it late, failed to release it from a queue, or delayed the correction. | I14: Plan / Vendor | J14: Require a plan-side root-cause analysis and corrective-action plan; correct encounter workflow and submit if an allowable window remains. | K14: Plan claims operations, encounter-data operations, delegated entity, or encounter vendor.
A15: Q-01 | B15: A + Q | C15: A | D15: Q | E15: MAO-004 #23 Service Type + prior/current #25/#27 results + source CPT/HCPCS + the applicable quarterly allowable-code list. CPT/HCPCS is external to MAO-004. | F15: CMS allowed a record after a quarterly CPT/HCPCS update or reprocessing. | G15: Prior and current MAO-004 records; encounter ICN; service line; reconciliation result. | H15: The same encounter moved from a prior disallowed outcome to allowed because CMS updated or reapplied filtering logic. | I15: CMS / Plan reconciliation | J15: No provider correction is normally required. Confirm the favorable result is reflected in downstream reconciliation. | K15: Plan risk-adjustment reconciliation and reporting.
... A21: Health Trixss operational reference | Fields #25 and #27 identify the CMS-coded outcome; the root cause is confirmed with Field #23 and other MAO-004 fields plus MAO-002 and source-to-EDPS evidence. | B21: Health Trixss operational reference | Fields #25 and #27 identify the CMS-coded outcome; the root cause is confirmed with Field #23 and other MAO-004 fields plus MAO-002 and source-to-EDPS evidence. | C21: Health Trixss operational reference | Fields #25 and #27 identify the CMS-coded outcome; the root cause is confirmed with Field #23 and other MAO-004 fields plus MAO-002 and source-to-EDPS evidence. | D21: Health Trixss operational reference | Fields #25 and #27 identify the CMS-coded outcome; the root cause is confirmed with Field #23 and other MAO-004 fields plus MAO-002 and source-to-EDPS evidence. | E21: Health Trixss operational reference | Fields #25 and #27 identify the CMS-coded outcome; the root cause is confirmed with Field #23 and other MAO-004 fields plus MAO-002 and source-to-EDPS evidence. | F21: Health Trixss operational reference | Fields #25 and #27 identify the CMS-coded outcome; the root cause is confirmed with Field #23 and other MAO-004 fields plus MAO-002 and source-to-EDPS evidence. | G21: Health Trixss operational reference | Fields #25 and #27 identify the CMS-coded outcome; the root cause is confirmed with Field #23 and other MAO-004 fields plus MAO-002 and source-to-EDPS evidence. | H21: Health Trixss operational reference | Fields #25 and #27 identify the CMS-coded outcome; the root cause is confirmed with Field #23 and other MAO-004 fields plus MAO-002 and source-to-EDPS evidence. | I21: Health Trixss operational reference | Fields #25 and #27 identify the CMS-coded outcome; the root cause is confirmed with Field #23 and other MAO-004 fields plus MAO-002 and source-to-EDPS evidence. | J21: Health Trixss operational reference | Fields #25 and #27 identify the CMS-coded outcome; the root cause is confirmed with Field #23 and other MAO-004 fields plus MAO-002 and source-to-EDPS evidence. | K21: Health Trixss operational reference | Fields #25 and #27 identify the CMS-coded outcome; the root cause is confirmed with Field #23 and other MAO-004 fields plus MAO-002 and source-to-EDPS evidence.

Sheet Control by Layer
A1: HEALTH TRIXSS | Root-Cause Control by Operational Layer
A2: Use this sheet to determine whether a provider group can directly correct the root cause, must coordinate with the MA plan, or can only escalate.
A4: Root-Cause Layer | B4: Typical Examples | C4: Provider Control | D4: Where the Fix Occurs | E4: Plan / Vendor Responsibility | F4: Recommended Owner | G4: Required Evidence
A5: Clinical documentation / EHR | B5: Unsupported diagnosis; omitted assessment; wrong service date; diagnosis not documented during an eligible encounter. | C5: Direct control over accurate, timely documentation and compliant clinical corrections. | D5: EHR note, diagnosis entry, addendum workflow, clinical documentation improvement process. | E5: Use only supported diagnoses and reconcile submitted encounter data. | F5: Medical director / CDI lead | G5: Signed medical record, addendum history, audit trail, and coding query.
A6: Coding and charge capture | B6: Wrong ICD-10-CM, CPT/HCPCS, modifier, units, or diagnosis-to-line linkage. | C6: Direct control when correction is supported by the medical record. | D6: Coding work queue, charge router, claim scrubber, practice-management system. | E6: Adjudicate the corrected claim and propagate corrected data into EDPS. | F6: Coding manager / revenue-cycle lead | G6: Coder validation, charge detail, original/corrected claim, and audit trail.
A7: Facility billing | B7: Wrong Type of Bill, frequency code, revenue code, discharge status, or institutional transaction type. | C7: Direct control over source UB-04/837I data. | D7: Hospital patient-accounting and institutional-billing systems. | E7: Accept corrected institutional claim and submit the corrected encounter. | F7: Facility billing director | G7: UB-04, 837I, claim history, payer acceptance, and supporting facility documentation.
A8: Claim transmission | B8: Clearinghouse rejection, claim never received, corrected claim not transmitted, or payer routing failure. | C8: Shared with the clearinghouse and payer. | D8: EDI gateway, clearinghouse portal, reject work queue, payer claim portal. | E8: Expose acceptance/rejection status and process the received transaction. | F8: Provider EDI lead | G8: 999, 277CA, payer acknowledgement, portal receipt, and transmission timestamps.
A9: Plan adjudication and encounter construction | B9: Plan changes, translates, combines, or omits claim fields when constructing the EDPS encounter. | C9: No direct EDPS control; provider can supply source evidence and challenge discrepancies. | D9: MA-plan claims platform, encounter warehouse, mapping engine, or vendor process. | E9: Correct mapping/construction logic and submit the accurate encounter. | F9: Plan claims and encounter-data operations | G9: Provider source claim, plan-adjudicated claim, encounter extract, and mapping specifications.
A10: MAO-002 / MAO-004 reconciliation | B10: Rejected service line, wrong active ICN, replacement not linked, claim accepted but diagnosis disallowed. | C10: Provider needs plan-provided detail before it can determine whether a source correction is possible. | D10: Plan encounter-reconciliation platform and exception-management work queue. | E10: Supply edit-level detail, identify the active record, and resubmit the correct transaction. | F10: Plan encounter-data reconciliation lead | G10: MAO-002 header/line results, MAO-004 result, ICNs, and submission history.
A11: CMS filtering rules | B11: Allowable CPT/HCPCS list, eligible Type-of-Bill list, service classification, or quarterly update. | C11: No control when the source claim is accurate. | D11: CMS filtering and reprocessing logic. | E11: Apply CMS rules accurately and reconcile subsequent updates. | F11: Plan regulatory / risk-adjustment team | G11: Applicable CMS guidance, service-year rule, and MAO-004 output.
A12: CMS submission deadline | B12: Original or corrected encounter submitted after a CMS cutoff. | C12: Provider controls its own upstream timeliness; no control over CMS deadline and limited control over plan delays. | D12: Provider timely-filing workflows and plan encounter-submission calendar. | E12: Submit timely, disclose missed deadlines, and distinguish provider delay from plan/vendor delay. | F12: Provider revenue-cycle executive and plan encounter-data executive | G12: Provider receipt date, plan receipt date, EDPS submission date, and deadline calendar.
A14: Health Trixss operational reference | Educational and workflow support only; apply current CMS guidance, contract terms, and compliance review.

Sheet MAO-002 Early Warning
A1: HEALTH TRIXSS | MAO-002 Early-Warning Crosswalk
A2: MAO-002 supplies encounter and line-level processing detail that helps discriminate root-cause scenarios; it must still be reconciled to provider source data and the plan-submitted encounter.
A3: MAO-002 is a root-cause input, not always the root cause by itself: the same edit may originate in provider source data, clearinghouse transformation, plan mapping, or encounter construction.
A4: MAO-002 Indicator | B4: Meaning | C4: Provider Action | D4: Provider Fix Location | E4: Plan Action | F4: Provider Control
A5: PA | B5: Preliminary allowable. | C5: Monitor the monthly MAO-004 for the final risk-adjustment status; correct only if source data are inaccurate. | D5: No routine source correction. | E5: Complete final MAO-004 reconciliation. | F5: No correction needed
A6: PD / PH | B6: Preliminary disallowable because no accepted allowable CPT/HCPCS was found. | C6: Confirm the procedure is accurate and determine whether the qualifying line was rejected. | D6: Coding, charge capture, claim scrubber, or clearinghouse. | E6: Provide line-level rejection detail and reprocess a corrected claim. | F6: High / Shared
A7: PD / PT | B7: Preliminary disallowable because Type of Bill was not allowable. | C7: Validate the institutional Type of Bill against the source claim and actual care setting. | D7: Facility patient-accounting / billing system. | E7: Reprocess corrected 837I and submit corrected encounter. | F7: High / Shared
A8: PN | B8: Preliminary not applicable. | C8: Review claim type and service classification. Do not automatically treat the result as a provider error. | D8: Provider billing only if source classification is wrong. | E8: Validate plan mapping and EDPS classification. | F8: Variable / Shared
A9: FR | B9: Final reject. | C9: Obtain the five-digit EDPS edit code, identify the affected header or line, and submit an accurate correction. | D9: Depends on the exact edit: EHR, coding, billing, facility billing, or clearinghouse. | E9: Supply the exact edit, accept the corrected claim, and resubmit to CMS. | F9: Variable
A12: Health Trixss operational reference | Educational and workflow support only; apply current CMS guidance, contract terms, and compliance review.

Sheet Plan Data Requirements
A1: HEALTH TRIXSS | Provider Guide to MAO-004 Root-Cause Analysis
A2: How provider groups should use the matrix, what information must be requested from the MA plan, and how confirmed root causes affect revenue-cycle and risk-adjustment operations.
A4: Purpose and Operating Context
A5: The MAO-004 report tells the Medicare Advantage organization whether CMS allowed, disallowed, or classified a diagnosis as not applicable for risk adjustment. It does not, by itself, identify the operational root cause or prove that the provider made an error. The provider group should use the Provider Action Matrix as an exception-triage and accountability tool: first identify the CMS outcome using Fields #25 and #27; then use Field #23, MAO-002 line-level results, source-claim values, plan-submitted encounter values, linked-record fields, and submission timestamps to determine the actual scenario. Only after that reconciliation should work be assigned to coding, billing, EDI, clinical documentation, payer escalation, or plan/vendor operations.
A8: How the Provider Group Should Use the Matrix
A9: Step | B9: Provider Question | C9: Provider Action | D9: Evidence Used | E9: Decision / Output | F9: Operational Impact
A10: 1 | B10: What coded outcome did CMS return? | C10: Locate the matching matrix row using MAO-004 Status #25 and Reason #27. | D10: MAO-004 result, service date, encounter ICN, diagnosis. | E10: Outcome family identified: allowed, H, T, D, N, Q, or linked/blank. | F10: Prevents the case from being routed to the wrong operational team.
A11: 2 | B11: Which root-cause fields apply to this outcome? | C11: Use the matrix’s Root-Cause Fields column to identify the next data required. | D11: Field #23; CPT/HCPCS; Type of Bill; timing fields; linked ICNs; add/delete fields. | E11: Required evidence checklist established for the specific scenario. | F11: Reduces unnecessary corrected claims and incomplete payer inquiries.
A12: 3 | B12: Does the provider source claim match what the plan submitted to EDPS? | C12: Compare provider 837/claim data with the plan-adjudicated claim and EDPS encounter extract. | D12: Source CPT/HCPCS, Type of Bill, claim type, line status, diagnoses, encounter values. | E12: Root cause assigned to provider data, clearinghouse transformation, plan/vendor mapping, or CMS filtering. | F12: Protects the provider from being assigned responsibility for plan-controlled defects.
A13: 4 | B13: Can the provider correct the issue? | C13: Validate the medical record and determine whether a supported source-claim correction exists. | D13: Medical record, charge detail, coding review, claim history, MAO-002 edit detail. | E13: Corrected claim, no provider correction, or plan-side remediation and escalation. | F13: Directs work to coding, billing, EDI, clinical documentation, or payer relations.
A14: 5 | B14: Was the correction completed before the applicable deadline? | C14: Track provider submission, plan receipt, EDPS resubmission, and final MAO-004 disposition. | D14: Provider/clearinghouse timestamps, plan timestamps, CMS deadline, replacement/void ICNs. | E14: Exception closed, escalated, or classified as no longer recoverable for the payment run. | F14: Supports financial forecasting, SLA monitoring, and prevention of repeat failures.
A16: Operational Context and Impact
A17: Operational Area | B17: How the Matrix Is Used | C17: Provider Control | D17: Impact of Incorrect Assignment | E17: Primary Owner | F17: Suggested Operational Measure
A18: Coding and charge capture | B18: Determine whether CPT/HCPCS, diagnosis linkage, modifier, or an omitted service line requires a supported source correction. | C18: High when the source claim is inaccurate. | D18: Incorrect resubmissions, compliance risk, repeated disallowances, and wasted coder time. | E18: Coding manager / revenue-cycle lead | F18: % of H scenarios confirmed as provider-source defects
A19: Facility billing | B19: Validate whether the Type of Bill accurately reflects the documented care setting and transaction. | C19: High when the source 837I/UB-04 is inaccurate. | D19: Repeated T outcomes, incorrect claim corrections, and delayed encounter replacement. | E19: Facility billing director | F19: T scenarios resolved by source correction vs. plan correction
A20: Claims and EDI | B20: Compare the provider transaction, clearinghouse acknowledgement, payer receipt, and plan encounter values. | C20: Shared across provider, clearinghouse, and plan. | D20: Unresolved transmission defects, duplicate work, and inability to prove timely submission. | E20: Provider EDI lead | F20: Exceptions with complete 999/277CA and payer-receipt evidence
A21: Payer relations and escalation | B21: Demonstrate when the source claim was correct and the root cause resides in plan mapping, linkage, timing, or encounter construction. | C21: Provider can document and escalate but cannot directly fix EDPS. | D21: Provider is held accountable for plan-controlled defects; corrective action stalls. | E21: Payer relations / delegated oversight | F21: Plan-controlled exceptions resolved within SLA
A22: Compliance and audit readiness | B22: Document why a correction was or was not made and preserve the source-to-EDPS evidence trail. | C22: Shared accountability. | D22: Unsupported code changes, weak audit defense, and inability to demonstrate appropriate oversight. | E22: Compliance / internal audit | F22: % exceptions with documented root cause, owner, and closure evidence
A24: Detailed Data Requirements for Root-Cause Confirmation
A25: Required Data Point | B25: How the Provider Uses It | C25: Root-Cause Decision Enabled | D25: Who Must Supply / System of Record | E25: Provider Action If Missing | F25: Operational Impact If Unavailable
A26: MAO-004 Field #25 — Allowed/Disallowed Status | B26: Identify whether CMS coded the diagnosis as allowed, disallowed, not applicable, or blank. | C26: Establishes the primary outcome category. | D26: MA plan from CMS MAO-004 response. | E26: Request the complete MAO-004 record, not a summarized rejection label. | F26: The provider cannot select the correct matrix branch.
A27: MAO-004 Field #27 — Allowed/Disallowed Reason | B27: Identify the H, T, D, Q, N, or blank outcome family. | C27: Determines the initial root-cause investigation path. | D27: MA plan from CMS MAO-004 response. | E27: Request the exact reason value and the related diagnosis row. | F27: The case may be routed to the wrong team or incorrectly classified as provider error.
A28: MAO-004 Field #23 — Service Type | B28: Determine whether the outcome should be tested using CPT/HCPCS, Type of Bill, deadline logic, or not-applicable classification. | C28: Selects the correct root-cause fields used with #25 and #27. | D28: MA plan from CMS MAO-004 response. | E28: Do not proceed with H, T, or N root-cause assignment until supplied. | F28: CPT/HCPCS and Type-of-Bill scenarios may be confused.
A29: Provider claim number and payer claim-control number | B29: Locate the provider source transaction and payer-adjudicated claim. | C29: Links the CMS outcome to the exact operational claim record. | D29: Provider billing system and MA-plan claims platform. | E29: Open a payer data request and hold provider correction activity. | F29: Teams may review or correct the wrong claim.
A30: Encounter ICN and original/linked ICN | B30: Trace the active CMS encounter family, replacements, voids, and linked transactions. | C30: Identifies stale records, incorrect linkage, and corrections that did not become active. | D30: MA plan encounter-data system / CMS response. | E30: Escalate to the plan encounter-reconciliation team. | F30: A valid provider correction may appear unresolved because the wrong encounter remains active.
A31: MAO-004 Fields #11, #13, #15, #31, #33, and #35 | B31: Review transaction type, linked ICN status, diagnosis, and add/delete activity. | C31: Distinguishes standard outcomes from void, replacement, chart-review add, or delete scenarios. | D31: MA plan from CMS MAO-004 detail. | E31: Request the full fixed-length record or a complete field-level extract. | F31: The provider may submit unnecessary claims or fail to identify an incorrect delete/void.
A32: MAO-002 header status | B32: Determine whether the encounter header itself was accepted or rejected. | C32: Separates encounter rejection from line-level service filtering. | D32: MA plan from CMS MAO-002 response. | E32: Request the associated MAO-002 record before assigning corrective ownership. | F32: Provider work may target a service line when the encounter header is the actual problem.
A33: MAO-002 line number, line status, edit code, and edit description | B33: Identify the exact rejected service line and processing edit. | C33: Distinguishes a rejected qualifying CPT/HCPCS line from an absent or legitimately nonqualifying service. | D33: MA plan from CMS MAO-002 response. | E33: Reject generic notices such as 'invalid CPT' without the line and edit detail. | F33: The provider cannot know which data element to correct.
A34: Provider source CPT/HCPCS, Type of Bill, claim type, and diagnosis linkage | B34: Confirm what the provider actually billed and whether it matches the medical record. | C34: Determines whether the defect originated in provider coding or claim construction. | D34: Provider EHR, charge capture, billing system, and 837 archive. | E34: Retrieve the original outbound transaction before making corrections. | F34: Unsupported corrections and inaccurate accountability assignments may occur.
A35: Plan-adjudicated claim and EDPS encounter values | B35: Compare plan-received and plan-submitted values to the provider source claim. | C35: Identifies omissions, transformations, mapping errors, and stale values introduced downstream. | D35: MA-plan claims and encounter-data systems / delegated vendor. | E35: Escalate as a plan data requirement; do not assume the provider claim was wrong. | F35: Plan-controlled defects may remain unresolved and be repeatedly returned to the provider.
A36: Medical record and charge-detail support | B36: Validate whether a proposed claim correction is clinically and operationally supported. | C36: Confirms the correct source value and protects against outcome-driven coding changes. | D36: Provider EHR, CDI, coding, and charge-detail systems. | E36: Route to coding/CDI review; do not submit a speculative correction. | F36: Compliance exposure and unsupported risk-adjustment submissions.
... A42: Resubmission acknowledgement and final MAO-002/MAO-004 disposition | B42: Confirm that the correction reached CMS and changed the active outcome as intended. | C42: Provides objective closure evidence. | D42: MA plan from CMS response and reconciliation system. | E42: Keep the exception open and escalate if final evidence is not supplied. | F42: Cases may be closed administratively even though CMS still shows the original outcome.
A44: Provider Operating Rule: Do not create a corrected claim merely because the MAO-004 result is disallowed. First confirm that the provider source data are factually wrong and that the medical record supports the correction. When the provider source claim is accurate, the case should be routed to the MA plan or delegated encounter vendor with the source-to-EDPS comparison and timing evidence.
A48: Health Trixss operational reference | Use current CMS guidance, contractual requirements, and compliance review when implementing provider corrective-action workflows.

Sheet 2025 Annual Waterfall
A1: HEALTH TRIXSS | 2025 Annual Provider-to-Plan-to-CMS Waterfall
A2: Illustrative full-year reconciliation of provider encounter submissions, health-plan processing, CMS MAO-002 responses, MAO-004 diagnosis outcomes, corrective action, and final allowed diagnoses.
A4: Model context: Counts are synthetic and designed to represent a realistic mid-sized provider group. The first waterfall is encounter-level through MAO-002 acceptance. The second waterfall changes units to diagnosis records because MAO-004 reports diagnosis-level risk-adjustment eligibility. The model is fully formula-driven from the editable monthly assumptions.
A8: Provider Encounters | C8: Plan Acceptance | E8: MAO-002 Acceptance | G8: Diagnoses Evaluated | I8: Initial Allowed | K8: Final Allowed | M8: Recovery Lift
A9: ='2025 Monthly Detail'!B18 -> 149000 | C9: ='2025 Monthly Detail'!D18/'2025 Monthly Detail'!B18 -> 0.97722819 | E9: ='2025 Monthly Detail'!H18/'2025 Monthly Detail'!F18 -> 0.98289383 | G9: ='2025 Monthly Detail'!J18 -> 367465 | I9: ='2025 Monthly Detail'!AP18 -> 0.89043855 | K9: ='2025 Monthly Detail'!AN18 -> 0.93661709 | M9: ='2025 Monthly Detail'!AQ18 -> 0.046178548
A12: Encounter Submission Waterfall — Encounter-Level Counts | H12: MAO-004 Diagnosis Waterfall — Diagnosis-Level Counts
A13: Stage | B13: Count | C13: Loss vs Prior Stage | D13: Stage Yield | E13: % of Provider Submission | F13: Operational Interpretation | H13: Waterfall Stage | I13: Movement | J13: Ending Balance | K13: % of Diagnoses | L13: Outcome Family | M13: Provider Interpretation | N13: Control Owner
A14: Provider encounters submitted | B14: ='2025 Monthly Detail'!B18 -> 149000 | C14: 0 | D14: 1 | E14: 1 | F14: Provider group transmits original and corrected encounter/claim data to the MA plan. | H14: Diagnoses evaluated on MAO-004 | I14: ='2025 Monthly Detail'!J18 -> 367465 | J14: =I14 -> 367465 | K14: =ABS(I14)/'2025 Monthly Detail'!J18 -> 1 | L14: Starting population | M14: Diagnosis records on MAO-002 accepted encounters. | N14: Plan/CMS response
A15: Accepted by health plan | B15: ='2025 Monthly Detail'!D18 -> 145607 | C15: =B14-B15 -> 3393 | D15: =B15/B14 -> 0.97722819 | E15: =B15/B14 -> 0.97722819 | F15: Plan intake rejects are removed; accepted records enter plan processing. | H15: Less: D + H | I15: =-'2025 Monthly Detail'!M18 -> -23185 | J15: =J14+I15 -> 344280 | K15: =ABS(I15)/'2025 Monthly Detail'!J18 -> 0.063094444 | L15: CPT/HCPCS filter | M15: No accepted allowable procedure line was found. | N15: Provider/shared/plan/CMS
A16: Submitted to EDPS | B16: ='2025 Monthly Detail'!F18 -> 144860 | C16: =B15-B16 -> 747 | D16: =B16/B15 -> 0.99486975 | E16: =B16/B14 -> 0.97221477 | F16: Plan holds and unresolved encounter edits are removed before CMS submission. | H16: Less: D + T | I16: =-'2025 Monthly Detail'!N18 -> -4416 | J16: =J15+I16 -> 339864 | K16: =ABS(I16)/'2025 Monthly Detail'!J18 -> 0.012017471 | L16: Type-of-Bill filter | M16: Institutional Type of Bill was not allowable. | N16: Provider/shared/plan/CMS
A17: Accepted on MAO-002 | B17: ='2025 Monthly Detail'!H18 -> 142382 | C17: =B16-B17 -> 2478 | D17: =B17/B16 -> 0.98289383 | E17: =B17/B14 -> 0.95558389 | F17: CMS accepts the encounter header/line combination for downstream diagnosis filtering. | H17: Less: D + D | I17: =-'2025 Monthly Detail'!O18 -> -2277 | J17: =J16+I17 -> 337587 | K17: =ABS(I17)/'2025 Monthly Detail'!J18 -> 0.0061965085 | L17: Deadline condition | M17: Submission was outside the applicable risk-adjustment deadline condition. | N17: Provider or plan/vendor
H18: Less: N + N | I18: =-'2025 Monthly Detail'!P18 -> -8912 | J18: =J17+I18 -> 328675 | K18: =ABS(I18)/'2025 Monthly Detail'!J18 -> 0.02425265 | L18: Not applicable | M18: Service type is not applicable for risk adjustment. | N18: CMS rule / classification
H19: Less: linked / blank | I19: =-'2025 Monthly Detail'!Q18 -> -1470 | J19: =J18+I19 -> 327205 | K19: =ABS(I19)/'2025 Monthly Detail'!J18 -> 0.004000381 | L19: Linked transaction | M19: Void, replacement, delete, or linked-record transaction without standard eligibility. | N19: Shared / plan-led
A20: Annual Root-Cause Ownership and Corrective Workload | H20: Initial allowed subtotal | I20: =SUBTOTAL(109,I14:I19) -> 327205 | J20: ='2025 Monthly Detail'!R18 -> 327205 | K20: =ABS(I20)/'2025 Monthly Detail'!J18 -> 0.89043855 | L20: A + blank and A + Q | M20: Diagnoses initially allowed before corrective action. | N20: CMS outcome
A21: Root-Cause Owner | B21: Identified Records | C21: Corrections Submitted | D21: Additional Allowed | E21: Remaining / No Recovery | F21: Operational Use | H21: Add: recovered H | I21: ='2025 Monthly Detail'!AH18 -> 14240 | J21: =J20+I21 -> 341445 | K21: =ABS(I21)/'2025 Monthly Detail'!J18 -> 0.03875199 | L21: Corrected H | M21: Supported provider or plan correction becomes allowed. | N21: Provider/shared/plan
A22: Provider-controlled source/timing | B22: ='2025 Monthly Detail'!S18+'2025 Monthly Detail'!W18+'2025 Monthly Detail'!Z18 -> 12308 | C22: ='2025 Monthly Detail'!AE18 -> 10093 | D22: =ROUND('2025 Monthly Detail'!S18*'2025 Model Assumptions'!$B$15*'2025 Model Assumptions'!$B$18+'2025 Monthly Detail'!W18*'2025 Model Assumptions'!$B$15*'2025 Model Assumptions'!$B$19+'2025 Monthly Detail'!Z18*'2025 Model Assumptions'!$B$20,0) -> 8802 | E22: =B22-D22 -> 3506 | F22: Coding, billing, EDI, and timely-submission work queues. | H22: Add: recovered T | I22: ='2025 Monthly Detail'!AI18 -> 2105 | J22: =J21+I22 -> 343550 | K22: =ABS(I22)/'2025 Monthly Detail'!J18 -> 0.0057284367 | L22: Corrected T | M22: Supported institutional correction becomes allowed. | N22: Provider/plan
A23: Shared MAO-002/edit-dependent | B23: ='2025 Monthly Detail'!T18 -> 5332 | C23: ='2025 Monthly Detail'!AF18 -> 4265 | D23: =ROUND('2025 Monthly Detail'!T18*'2025 Model Assumptions'!$B$16*'2025 Model Assumptions'!$B$18,0) -> 3967 | E23: =B23-D23 -> 1365 | F23: Requires plan edit detail and source-to-EDPS reconciliation. | H23: Add: recovered D | I23: ='2025 Monthly Detail'!AJ18 -> 624 | J23: =J22+I23 -> 344174 | K23: =ABS(I23)/'2025 Monthly Detail'!J18 -> 0.0016981209 | L23: Recovered timing | M23: Late-condition record is recovered before an applicable final cutoff. | N23: Provider/plan
A24: Plan/vendor-controlled | B24: ='2025 Monthly Detail'!U18+'2025 Monthly Detail'!X18+'2025 Monthly Detail'!AA18 -> 5838 | C24: ='2025 Monthly Detail'!AG18 -> 5139 | D24: ='2025 Monthly Detail'!AK18-D22-D23 -> 4200 | E24: =B24-D24 -> 1638 | F24: Plan mapping, linkage, encounter construction, and timing escalation. | H24: Final allowed diagnoses | I24: =I20+I21+I22+I23 -> 344174 | J24: ='2025 Monthly Detail'!AL18 -> 344174 | K24: =ABS(I24)/'2025 Monthly Detail'!J18 -> 0.93661709 | L24: Final modeled outcome | M24: Initial allowed plus successful corrective recovery. | N24: Plan reconciliation
A25: CMS rule / no provider defect | B25: ='2025 Monthly Detail'!V18+'2025 Monthly Detail'!Y18+'2025 Monthly Detail'!P18+'2025 Monthly Detail'!Q18 -> 16782 | C25: 0 | D25: 0 | E25: =B25 -> 16782 | F25: No source correction; retain evidence and reconcile other eligible encounters.
A26: Total exception population | B26: =SUM(B22:B25) -> 40260 | C26: =SUM(C22:C25) -> 19497 | D26: =SUM(D22:D25) -> 16969 | E26: =SUM(E22:E25) -> 23291 | F26: All initially non-allowed, not-applicable, and linked diagnosis records. | G26: ='2025 Monthly Detail'!AK18-D26 -> 0
A29: Monthly Allowed-Rate Trend
A30: Month | B30: Initial Allowed % | C30: Final Allowed % | D30: Recovery Lift %
A31: Jan | B31: ='2025 Monthly Detail'!AP6 -> 0.87802455 | C31: ='2025 Monthly Detail'!AN6 -> 0.93312283 | D31: ='2025 Monthly Detail'!AQ6 -> 0.055098276
A32: Feb | B32: ='2025 Monthly Detail'!AP7 -> 0.87997959 | C32: ='2025 Monthly Detail'!AN7 -> 0.93352043 | D32: ='2025 Monthly Detail'!AQ7 -> 0.053540839
A33: Mar | B33: ='2025 Monthly Detail'!AP8 -> 0.88200391 | C33: ='2025 Monthly Detail'!AN8 -> 0.93382105 | D33: ='2025 Monthly Detail'!AQ8 -> 0.05181714
A34: Apr | B34: ='2025 Monthly Detail'!AP9 -> 0.88501195 | C34: ='2025 Monthly Detail'!AN9 -> 0.93489575 | D34: ='2025 Monthly Detail'!AQ9 -> 0.049883801
A35: May | B35: ='2025 Monthly Detail'!AP10 -> 0.88701593 | C35: ='2025 Monthly Detail'!AN10 -> 0.93563835 | D35: ='2025 Monthly Detail'!AQ10 -> 0.048622418
A36: Jun | B36: ='2025 Monthly Detail'!AP11 -> 0.88899098 | C36: ='2025 Monthly Detail'!AN11 -> 0.93568499 | D36: ='2025 Monthly Detail'!AQ11 -> 0.046694011
A37: Jul | B37: ='2025 Monthly Detail'!AP12 -> 0.8909778 | C37: ='2025 Monthly Detail'!AN12 -> 0.93642224 | D37: ='2025 Monthly Detail'!AQ12 -> 0.045444441
A38: Aug | B38: ='2025 Monthly Detail'!AP13 -> 0.89301662 | C38: ='2025 Monthly Detail'!AN13 -> 0.93674026 | D38: ='2025 Monthly Detail'!AQ13 -> 0.043723642
A39: Sep | B39: ='2025 Monthly Detail'!AP14 -> 0.89498981 | C39: ='2025 Monthly Detail'!AN14 -> 0.93786606 | D39: ='2025 Monthly Detail'!AQ14 -> 0.042876241
A40: Oct | B40: ='2025 Monthly Detail'!AP15 -> 0.89799448 | C40: ='2025 Monthly Detail'!AN15 -> 0.93916684 | D40: ='2025 Monthly Detail'!AQ15 -> 0.041172366
A41: Nov | B41: ='2025 Monthly Detail'!AP16 -> 0.90098569 | C41: ='2025 Monthly Detail'!AN16 -> 0.94063593 | D41: ='2025 Monthly Detail'!AQ16 -> 0.039650238
A42: Dec | B42: ='2025 Monthly Detail'!AP17 -> 0.90300307 | C42: ='2025 Monthly Detail'!AN17 -> 0.94092966 | D42: ='2025 Monthly Detail'!AQ17 -> 0.037926592
A45: Waterfall Reconciliation Controls
A46: Control | B46: Formula Result | C46: Expected | D46: Status | E46: Purpose | F46: Owner
A47: Encounter waterfall | B47: ='2025 Monthly Detail'!B18-'2025 Monthly Detail'!C18-'2025 Monthly Detail'!E18-'2025 Monthly Detail'!G18-'2025 Monthly Detail'!H18 -> 0 | C47: 0 | D47: =IF(B47=C47,"PASS","REVIEW") -> PASS | E47: Provider submissions must reconcile to plan rejects, plan holds, MAO-002 rejects, and accepted encounters. | F47: Data operations
A48: Diagnosis waterfall | B48: ='2025 Monthly Detail'!AO18 -> 0 | C48: 0 | D48: =IF(B48=C48,"PASS","REVIEW") -> PASS | E48: Diagnoses must reconcile to final allowed, remaining H/T/D, N/N, and linked/blank. | F48: Risk-adjustment operations
A49: Correction lift | B49: ='2025 Monthly Detail'!AL18-'2025 Monthly Detail'!R18-'2025 Monthly Detail'!AK18 -> 0 | C49: 0 | D49: =IF(B49=C49,"PASS","REVIEW") -> PASS | E49: Final allowed minus initial allowed must equal total additional allowed. | F49: Reconciliation team

Sheet 2025 Monthly Detail
A1: HEALTH TRIXSS | 2025 Monthly Provider-to-CMS Submission Detail
A2: Formula-driven monthly reconciliation from provider encounter submission through plan intake, MAO-002 processing, MAO-004 diagnosis outcomes, corrective action, and final allowed diagnoses.
A3: Encounter Ops View
A4: Provider Submission | C4: Health Plan Intake / EDPS | G4: MAO-002 Response | I4: MAO-004 Diagnosis Outcomes | S4: Root-Cause Allocation | AB4: Corrective Workload | AH4: Recovery and Final Outcome | AN4: Rates and Controls
A5: Month | B5: Provider Encounters Submitted | C5: Plan Intake Rejects | D5: Plan Accepted | E5: Plan EDPS Holds | F5: EDPS Submitted | G5: MAO-002 Rejects | H5: MAO-002 Accepted | I5: Avg Dx / Accepted Encounter | J5: Diagnoses Evaluated | K5: A + blank | L5: A + Q | M5: D + H | N5: D + T | O5: D + D | P5: N + N | Q5: Linked / Blank | R5: Initial Allowed | S5: H Provider | T5: H Shared/Edit | U5: H Plan/Vendor | V5: H No Defect | W5: T Provider | X5: T Plan/Vendor | Y5: T No Defect | Z5: D Provider Late | AA5: D Plan Late | AB5: Provider Candidates | AC5: Shared Candidates | AD5: Plan Candidates | AE5: Provider Corrections Submitted | AF5: Shared Corrections Submitted | AG5: Plan Corrections Submitted | AH5: Additional Allowed H | AI5: Additional Allowed T | AJ5: Additional Allowed D | AK5: Total Additional Allowed | AL5: Final Allowed Diagnoses | AM5: Remaining H/T/D | AN5: Final Allowed % | AO5: Reconciliation Check | AP5: Initial Allowed % | AQ5: Recovery Lift %
A6: ='2025 Model Assumptions'!A25 -> 45658 | B6: ='2025 Model Assumptions'!B25 -> 11850 | C6: =ROUND(B6*'2025 Model Assumptions'!C25,0) -> 344 | D6: =B6-C6 -> 11506 | E6: =ROUND(D6*'2025 Model Assumptions'!D25,0) -> 81 | F6: =D6-E6 -> 11425 | G6: =ROUND(F6*'2025 Model Assumptions'!E25,0) -> 240 | H6: =F6-G6 -> 11185 | I6: ='2025 Model Assumptions'!F25 -> 2.52 | J6: =ROUND(H6*I6,0) -> 28186 | K6: =ROUND(J6*'2025 Model Assumptions'!G25,0) -> 24663 | L6: =ROUND(J6*'2025 Model Assumptions'!H25,0) -> 85 | M6: =ROUND(J6*'2025 Model Assumptions'!I25,0) -> 2086 | N6: =ROUND(J6*'2025 Model Assumptions'!J25,0) -> 423 | O6: =ROUND(J6*'2025 Model Assumptions'!K25,0) -> 254 | P6: =ROUND(J6*'2025 Model Assumptions'!L25,0) -> 564 | Q6: =J6-SUM(K6:P6) -> 111 | R6: =K6+L6 -> 24748 | S6: =ROUND(M6*'2025 Model Assumptions'!$B$6,0) -> 876 | T6: =ROUND(M6*'2025 Model Assumptions'!$B$7,0) -> 480 | U6: =ROUND(M6*'2025 Model Assumptions'!$B$8,0) -> 313 | V6: =M6-SUM(S6:U6) -> 417 | W6: =ROUND(N6*'2025 Model Assumptions'!$B$10,0) -> 148 | X6: =ROUND(N6*'2025 Model Assumptions'!$B$11,0) -> 106 | Y6: =N6-W6-X6 -> 169 | Z6: =ROUND(O6*'2025 Model Assumptions'!$B$13,0) -> 114 | AA6: =O6-Z6 -> 140 | AB6: =S6+W6+Z6 -> 1138 | AC6: =T6 -> 480 | AD6: =U6+X6+AA6 -> 559 | AE6: =ROUND(AB6*'2025 Model Assumptions'!$B$15,0) -> 933 | AF6: =ROUND(AC6*'2025 Model Assumptions'!$B$16,0) -> 384 | AG6: =ROUND(AD6*'2025 Model Assumptions'!$B$17,0) -> 492 | AH6: =ROUND(S6*'2025 Model Assumptions'!$B$15*'2025 Model Assumptions'!$B$18+T6*'2025 Model Assumptions'!$B$16*'2025 Model Assumptions'!$B$18+U6*'2025 Model Assumptions'!$B$17*'2025 Model Assumptions'!$B$18,0) -> 1281 | AI6: =ROUND(W6*'2025 Model Assumptions'!$B$15*'2025 Model Assumptions'!$B$19+X6*'2025 Model Assumptions'!$B$17*'2025 Model Assumptions'!$B$19,0) -> 202 | AJ6: =ROUND(Z6*'2025 Model Assumptions'!$B$20+AA6*'2025 Model Assumptions'!$B$21,0) -> 70 | AK6: =SUM(AH6:AJ6) -> 1553 | AL6: =R6+AK6 -> 26301 | AM6: =M6+N6+O6-AK6 -> 1210 | AN6: =AL6/J6 -> 0.93312283 | AO6: =J6-(AL6+AM6+P6+Q6) -> 0 | AP6: =R6/J6 -> 0.87802455 | AQ6: =AK6/J6 -> 0.055098276
A7: ='2025 Model Assumptions'!A26 -> 45689 | B7: ='2025 Model Assumptions'!B26 -> 11420 | C7: =ROUND(B7*'2025 Model Assumptions'!C26,0) -> 320 | D7: =B7-C7 -> 11100 | E7: =ROUND(D7*'2025 Model Assumptions'!D26,0) -> 78 | F7: =D7-E7 -> 11022 | G7: =ROUND(F7*'2025 Model Assumptions'!E26,0) -> 220 | H7: =F7-G7 -> 10802 | I7: ='2025 Model Assumptions'!F26 -> 2.54 | J7: =ROUND(H7*I7,0) -> 27437 | K7: =ROUND(J7*'2025 Model Assumptions'!G26,0) -> 24062 | L7: =ROUND(J7*'2025 Model Assumptions'!H26,0) -> 82 | M7: =ROUND(J7*'2025 Model Assumptions'!I26,0) -> 1975 | N7: =ROUND(J7*'2025 Model Assumptions'!J26,0) -> 412 | O7: =ROUND(J7*'2025 Model Assumptions'!K26,0) -> 219 | P7: =ROUND(J7*'2025 Model Assumptions'!L26,0) -> 576 | Q7: =J7-SUM(K7:P7) -> 111 | R7: =K7+L7 -> 24144 | S7: =ROUND(M7*'2025 Model Assumptions'!$B$6,0) -> 830 | T7: =ROUND(M7*'2025 Model Assumptions'!$B$7,0) -> 454 | U7: =ROUND(M7*'2025 Model Assumptions'!$B$8,0) -> 296 | V7: =M7-SUM(S7:U7) -> 395 | W7: =ROUND(N7*'2025 Model Assumptions'!$B$10,0) -> 144 | X7: =ROUND(N7*'2025 Model Assumptions'!$B$11,0) -> 103 | Y7: =N7-W7-X7 -> 165 | Z7: =ROUND(O7*'2025 Model Assumptions'!$B$13,0) -> 99 | AA7: =O7-Z7 -> 120 | AB7: =S7+W7+Z7 -> 1073 | AC7: =T7 -> 454 | AD7: =U7+X7+AA7 -> 519 | AE7: =ROUND(AB7*'2025 Model Assumptions'!$B$15,0) -> 880 | AF7: =ROUND(AC7*'2025 Model Assumptions'!$B$16,0) -> 363 | AG7: =ROUND(AD7*'2025 Model Assumptions'!$B$17,0) -> 457 | AH7: =ROUND(S7*'2025 Model Assumptions'!$B$15*'2025 Model Assumptions'!$B$18+T7*'2025 Model Assumptions'!$B$16*'2025 Model Assumptions'!$B$18+U7*'2025 Model Assumptions'!$B$17*'2025 Model Assumptions'!$B$18,0) -> 1213 | AI7: =ROUND(W7*'2025 Model Assumptions'!$B$15*'2025 Model Assumptions'!$B$19+X7*'2025 Model Assumptions'!$B$17*'2025 Model Assumptions'!$B$19,0) -> 196 | AJ7: =ROUND(Z7*'2025 Model Assumptions'!$B$20+AA7*'2025 Model Assumptions'!$B$21,0) -> 60 | AK7: =SUM(AH7:AJ7) -> 1469 | AL7: =R7+AK7 -> 25613 | AM7: =M7+N7+O7-AK7 -> 1137 | AN7: =AL7/J7 -> 0.93352043 | AO7: =J7-(AL7+AM7+P7+Q7) -> 0 | AP7: =R7/J7 -> 0.87997959 | AQ7: =AK7/J7 -> 0.053540839
A8: ='2025 Model Assumptions'!A27 -> 45717 | B8: ='2025 Model Assumptions'!B27 -> 12260 | C8: =ROUND(B8*'2025 Model Assumptions'!C27,0) -> 331 | D8: =B8-C8 -> 11929 | E8: =ROUND(D8*'2025 Model Assumptions'!D27,0) -> 72 | F8: =D8-E8 -> 11857 | G8: =ROUND(F8*'2025 Model Assumptions'!E27,0) -> 225 | H8: =F8-G8 -> 11632 | I8: ='2025 Model Assumptions'!F27 -> 2.55 | J8: =ROUND(H8*I8,0) -> 29662 | K8: =ROUND(J8*'2025 Model Assumptions'!G27,0) -> 26073 | L8: =ROUND(J8*'2025 Model Assumptions'!H27,0) -> 89 | M8: =ROUND(J8*'2025 Model Assumptions'!I27,0) -> 2076 | N8: =ROUND(J8*'2025 Model Assumptions'!J27,0) -> 415 | O8: =ROUND(J8*'2025 Model Assumptions'!K27,0) -> 237 | P8: =ROUND(J8*'2025 Model Assumptions'!L27,0) -> 653 | Q8: =J8-SUM(K8:P8) -> 119 | R8: =K8+L8 -> 26162 | S8: =ROUND(M8*'2025 Model Assumptions'!$B$6,0) -> 872 | T8: =ROUND(M8*'2025 Model Assumptions'!$B$7,0) -> 477 | U8: =ROUND(M8*'2025 Model Assumptions'!$B$8,0) -> 311 | V8: =M8-SUM(S8:U8) -> 416 | W8: =ROUND(N8*'2025 Model Assumptions'!$B$10,0) -> 145 | X8: =ROUND(N8*'2025 Model Assumptions'!$B$11,0) -> 104 | Y8: =N8-W8-X8 -> 166 | Z8: =ROUND(O8*'2025 Model Assumptions'!$B$13,0) -> 107 | AA8: =O8-Z8 -> 130 | AB8: =S8+W8+Z8 -> 1124 | AC8: =T8 -> 477 | AD8: =U8+X8+AA8 -> 545 | AE8: =ROUND(AB8*'2025 Model Assumptions'!$B$15,0) -> 922 | AF8: =ROUND(AC8*'2025 Model Assumptions'!$B$16,0) -> 382 | AG8: =ROUND(AD8*'2025 Model Assumptions'!$B$17,0) -> 480 | AH8: =ROUND(S8*'2025 Model Assumptions'!$B$15*'2025 Model Assumptions'!$B$18+T8*'2025 Model Assumptions'!$B$16*'2025 Model Assumptions'!$B$18+U8*'2025 Model Assumptions'!$B$17*'2025 Model Assumptions'!$B$18,0) -> 1274 | AI8: =ROUND(W8*'2025 Model Assumptions'!$B$15*'2025 Model Assumptions'!$B$19+X8*'2025 Model Assumptions'!$B$17*'2025 Model Assumptions'!$B$19,0) -> 198 | AJ8: =ROUND(Z8*'2025 Model Assumptions'!$B$20+AA8*'2025 Model Assumptions'!$B$21,0) -> 65 | AK8: =SUM(AH8:AJ8) -> 1537 | AL8: =R8+AK8 -> 27699 | AM8: =M8+N8+O8-AK8 -> 1191 | AN8: =AL8/J8 -> 0.93382105 | AO8: =J8-(AL8+AM8+P8+Q8) -> 0 | AP8: =R8/J8 -> 0.88200391 | AQ8: =AK8/J8 -> 0.05181714
A9: ='2025 Model Assumptions'!A28 -> 45748 | B9: ='2025 Model Assumptions'!B28 -> 12540 | C9: =ROUND(B9*'2025 Model Assumptions'!C28,0) -> 314 | D9: =B9-C9 -> 12226 | E9: =ROUND(D9*'2025 Model Assumptions'!D28,0) -> 73 | F9: =D9-E9 -> 12153 | G9: =ROUND(F9*'2025 Model Assumptions'!E28,0) -> 219 | H9: =F9-G9 -> 11934 | I9: ='2025 Model Assumptions'!F28 -> 2.56 | J9: =ROUND(H9*I9,0) -> 30551 | K9: =ROUND(J9*'2025 Model Assumptions'!G28,0) -> 26946 | L9: =ROUND(J9*'2025 Model Assumptions'!H28,0) -> 92 | M9: =ROUND(J9*'2025 Model Assumptions'!I28,0) -> 2077 | N9: =ROUND(J9*'2025 Model Assumptions'!J28,0) -> 397 | O9: =ROUND(J9*'2025 Model Assumptions'!K28,0) -> 214 | P9: =ROUND(J9*'2025 Model Assumptions'!L28,0) -> 703 | Q9: =J9-SUM(K9:P9) -> 122 | R9: =K9+L9 -> 27038 | S9: =ROUND(M9*'2025 Model Assumptions'!$B$6,0) -> 872 | T9: =ROUND(M9*'2025 Model Assumptions'!$B$7,0) -> 478 | U9: =ROUND(M9*'2025 Model Assumptions'!$B$8,0) -> 312 | V9: =M9-SUM(S9:U9) -> 415 | W9: =ROUND(N9*'2025 Model Assumptions'!$B$10,0) -> 139 | X9: =ROUND(N9*'2025 Model Assumptions'!$B$11,0) -> 99 | Y9: =N9-W9-X9 -> 159 | Z9: =ROUND(O9*'2025 Model Assumptions'!$B$13,0) -> 96 | AA9: =O9-Z9 -> 118 | AB9: =S9+W9+Z9 -> 1107 | AC9: =T9 -> 478 | AD9: =U9+X9+AA9 -> 529 | AE9: =ROUND(AB9*'2025 Model Assumptions'!$B$15,0) -> 908 | AF9: =ROUND(AC9*'2025 Model Assumptions'!$B$16,0) -> 382 | AG9: =ROUND(AD9*'2025 Model Assumptions'!$B$17,0) -> 466 | AH9: =ROUND(S9*'2025 Model Assumptions'!$B$15*'2025 Model Assumptions'!$B$18+T9*'2025 Model Assumptions'!$B$16*'2025 Model Assumptions'!$B$18+U9*'2025 Model Assumptions'!$B$17*'2025 Model Assumptions'!$B$18,0) -> 1276 | AI9: =ROUND(W9*'2025 Model Assumptions'!$B$15*'2025 Model Assumptions'!$B$19+X9*'2025 Model Assumptions'!$B$17*'2025 Model Assumptions'!$B$19,0) -> 189 | AJ9: =ROUND(Z9*'2025 Model Assumptions'!$B$20+AA9*'2025 Model Assumptions'!$B$21,0) -> 59 | AK9: =SUM(AH9:AJ9) -> 1524 | AL9: =R9+AK9 -> 28562 | AM9: =M9+N9+O9-AK9 -> 1164 | AN9: =AL9/J9 -> 0.93489575 | AO9: =J9-(AL9+AM9+P9+Q9) -> 0 | AP9: =R9/J9 -> 0.88501195 | AQ9: =AK9/J9 -> 0.049883801
A10: ='2025 Model Assumptions'!A29 -> 45778 | B10: ='2025 Model Assumptions'!B29 -> 12780 | C10: =ROUND(B10*'2025 Model Assumptions'!C29,0) -> 307 | D10: =B10-C10 -> 12473 | E10: =ROUND(D10*'2025 Model Assumptions'!D29,0) -> 62 | F10: =D10-E10 -> 12411 | G10: =ROUND(F10*'2025 Model Assumptions'!E29,0) -> 223 | H10: =F10-G10 -> 12188 | I10: ='2025 Model Assumptions'!F29 -> 2.57 | J10: =ROUND(H10*I10,0) -> 31323 | K10: =ROUND(J10*'2025 Model Assumptions'!G29,0) -> 27690 | L10: =ROUND(J10*'2025 Model Assumptions'!H29,0) -> 94 | M10: =ROUND(J10*'2025 Model Assumptions'!I29,0) -> 2067 | N10: =ROUND(J10*'2025 Model Assumptions'!J29,0) -> 407 | O10: =ROUND(J10*'2025 Model Assumptions'!K29,0) -> 219 | P10: =ROUND(J10*'2025 Model Assumptions'!L29,0) -> 720 | Q10: =J10-SUM(K10:P10) -> 126 | R10: =K10+L10 -> 27784 | S10: =ROUND(M10*'2025 Model Assumptions'!$B$6,0) -> 868 | T10: =ROUND(M10*'2025 Model Assumptions'!$B$7,0) -> 475 | U10: =ROUND(M10*'2025 Model Assumptions'!$B$8,0) -> 310 | V10: =M10-SUM(S10:U10) -> 414 | W10: =ROUND(N10*'2025 Model Assumptions'!$B$10,0) -> 142 | X10: =ROUND(N10*'2025 Model Assumptions'!$B$11,0) -> 102 | Y10: =N10-W10-X10 -> 163 | Z10: =ROUND(O10*'2025 Model Assumptions'!$B$13,0) -> 99 | AA10: =O10-Z10 -> 120 | AB10: =S10+W10+Z10 -> 1109 | AC10: =T10 -> 475 | AD10: =U10+X10+AA10 -> 532 | AE10: =ROUND(AB10*'2025 Model Assumptions'!$B$15,0) -> 909 | AF10: =ROUND(AC10*'2025 Model Assumptions'!$B$16,0) -> 380 | AG10: =ROUND(AD10*'2025 Model Assumptions'!$B$17,0) -> 468 | AH10: =ROUND(S10*'2025 Model Assumptions'!$B$15*'2025 Model Assumptions'!$B$18+T10*'2025 Model Assumptions'!$B$16*'2025 Model Assumptions'!$B$18+U10*'2025 Model Assumptions'!$B$17*'2025 Model Assumptions'!$B$18,0) -> 1269 | AI10: =ROUND(W10*'2025 Model Assumptions'!$B$15*'2025 Model Assumptions'!$B$19+X10*'2025 Model Assumptions'!$B$17*'2025 Model Assumptions'!$B$19,0) -> 194 | AJ10: =ROUND(Z10*'2025 Model Assumptions'!$B$20+AA10*'2025 Model Assumptions'!$B$21,0) -> 60 | AK10: =SUM(AH10:AJ10) -> 1523 | AL10: =R10+AK10 -> 29307 | AM10: =M10+N10+O10-AK10 -> 1170 | AN10: =AL10/J10 -> 0.93563835 | AO10: =J10-(AL10+AM10+P10+Q10) -> 0 | AP10: =R10/J10 -> 0.88701593 | AQ10: =AK10/J10 -> 0.048622418
A11: ='2025 Model Assumptions'!A30 -> 45809 | B11: ='2025 Model Assumptions'!B30 -> 12360 | C11: =ROUND(B11*'2025 Model Assumptions'!C30,0) -> 284 | D11: =B11-C11 -> 12076 | E11: =ROUND(D11*'2025 Model Assumptions'!D30,0) -> 60 | F11: =D11-E11 -> 12016 | G11: =ROUND(F11*'2025 Model Assumptions'!E30,0) -> 204 | H11: =F11-G11 -> 11812 | I11: ='2025 Model Assumptions'!F30 -> 2.58 | J11: =ROUND(H11*I11,0) -> 30475 | K11: =ROUND(J11*'2025 Model Assumptions'!G30,0) -> 27001 | L11: =ROUND(J11*'2025 Model Assumptions'!H30,0) -> 91 | M11: =ROUND(J11*'2025 Model Assumptions'!I30,0) -> 1950 | N11: =ROUND(J11*'2025 Model Assumptions'!J30,0) -> 366 | O11: =ROUND(J11*'2025 Model Assumptions'!K30,0) -> 183 | P11: =ROUND(J11*'2025 Model Assumptions'!L30,0) -> 762 | Q11: =J11-SUM(K11:P11) -> 122 | R11: =K11+L11 -> 27092 | S11: =ROUND(M11*'2025 Model Assumptions'!$B$6,0) -> 819 | T11: =ROUND(M11*'2025 Model Assumptions'!$B$7,0) -> 449 | U11: =ROUND(M11*'2025 Model Assumptions'!$B$8,0) -> 293 | V11: =M11-SUM(S11:U11) -> 389 | W11: =ROUND(N11*'2025 Model Assumptions'!$B$10,0) -> 128 | X11: =ROUND(N11*'2025 Model Assumptions'!$B$11,0) -> 92 | Y11: =N11-W11-X11 -> 146 | Z11: =ROUND(O11*'2025 Model Assumptions'!$B$13,0) -> 82 | AA11: =O11-Z11 -> 101 | AB11: =S11+W11+Z11 -> 1029 | AC11: =T11 -> 449 | AD11: =U11+X11+AA11 -> 486 | AE11: =ROUND(AB11*'2025 Model Assumptions'!$B$15,0) -> 844 | AF11: =ROUND(AC11*'2025 Model Assumptions'!$B$16,0) -> 359 | AG11: =ROUND(AD11*'2025 Model Assumptions'!$B$17,0) -> 428 | AH11: =ROUND(S11*'2025 Model Assumptions'!$B$15*'2025 Model Assumptions'!$B$18+T11*'2025 Model Assumptions'!$B$16*'2025 Model Assumptions'!$B$18+U11*'2025 Model Assumptions'!$B$17*'2025 Model Assumptions'!$B$18,0) -> 1198 | AI11: =ROUND(W11*'2025 Model Assumptions'!$B$15*'2025 Model Assumptions'!$B$19+X11*'2025 Model Assumptions'!$B$17*'2025 Model Assumptions'!$B$19,0) -> 175 | AJ11: =ROUND(Z11*'2025 Model Assumptions'!$B$20+AA11*'2025 Model Assumptions'!$B$21,0) -> 50 | AK11: =SUM(AH11:AJ11) -> 1423 | AL11: =R11+AK11 -> 28515 | AM11: =M11+N11+O11-AK11 -> 1076 | AN11: =AL11/J11 -> 0.93568499 | AO11: =J11-(AL11+AM11+P11+Q11) -> 0 | AP11: =R11/J11 -> 0.88899098 | AQ11: =AK11/J11 -> 0.046694011
